#VRML_SIM R2021a utf8
WorldInfo {
  basicTimeStep 16
  coordinateSystem "NUE"
  contactProperties [
    ContactProperties {
      material2 "slippy"
      coulombFriction [
        0
      ]
    }
    ContactProperties {
      material2 "block"
      coulombFriction [
        0.01
      ]
    }
  ]
}
Viewpoint {
  orientation -0.22507040732916345 -0.938199194480409 -0.26291744563835245 2.0115829582050284
  position -4.77790910549514 3.524659543321239 -2.156304529268869
}
TexturedBackground {
}
TexturedBackgroundLight {
}
Floor {
  size 2.4 2.4
  appearance Asphalt {
  }
}
DEF Block_R1 Solid {
  translation  -1.0665    0.0500   -0.2783
  children [
    DEF BOX_R Shape {
      appearance PBRAppearance {
        baseColor 1 0 0
        metalness 0
      }
      geometry Box {
        size 0.05 0.05 0.05
      }
    }
  ]
  name "solid(4)"
  contactMaterial "box"
  boundingObject USE BOX_R
  physics Physics {
  }
}
DEF Block_R2 Solid {
  translation -0.9467    0.0500    0.6240
  children [
    USE BOX_R
  ]
  name "solid(13)"
  contactMaterial "block"
  boundingObject USE BOX_R
  physics Physics {
  }
}
DEF Block_R3 Solid {
  translation 0.7601    0.0500    0.6937
  children [
    USE BOX_R
  ]
  name "solid(12)"
  boundingObject USE BOX_R
  physics Physics {
  }
}
DEF Block_R4 Solid {
  translation 0.4578    0.0500   -0.7358
  children [
    USE BOX_R
  ]
  name "solid(7)"
  boundingObject USE BOX_R
  physics Physics {
  }
}
DEF Block_B1 Solid {
  translation -0.4298    0.0500   -0.0241
  children [
    DEF BOX_B Shape {
      appearance PBRAppearance {
        baseColor 0 0 1
        metalness 0
      }
      geometry Box {
        size 0.05 0.05 0.05
      }
    }
  ]
  name "solid(8)"
  boundingObject USE BOX_B
  physics Physics {
  }
}
DEF Block_B2 Solid {
  translation 1.0580    0.0500   -0.1279
  children [
    USE BOX_B
  ]
  name "solid(9)"
  boundingObject USE BOX_B
  physics Physics {
  }
}
DEF Block_B3 Solid {
  translation -0.1440    0.0500    0.4920
  children [
    USE BOX_B
  ]
  name "solid(10)"
  boundingObject USE BOX_B
  physics Physics {
  }
}
DEF Block_B4 Solid {
  translation -1.0941    0.0500    0.3438
  children [
    USE BOX_B
  ]
  name "solid(11)"
  boundingObject USE BOX_B
  physics Physics {
  }
}
DEF Floor_colour Solid {
  translation 1 0.0001 1
  children [
    Shape {
      appearance PBRAppearance {
        baseColor 1 0 0
      }
      geometry Plane {
        size 0.4 0.4
      }
    }
  ]
  name "solid(6)"
}
DEF Floor_colour Solid {
  translation 1 0.0001 -1
  children [
    Shape {
      appearance PBRAppearance {
        baseColor 0 0 1
      }
      geometry Plane {
        size 0.4 0.4
      }
    }
  ]
  name "solid(5)"
}
DEF WALL_1 Solid {
  translation 1.2 0.05 0
  children [
    DEF WALL_SHAPE Shape {
      appearance PBRAppearance {
        baseColor 0 0.333333 0
        roughness 1
        metalness 0
      }
      geometry Box {
        size 0.02 0.1 2.38
      }
    }
  ]
  boundingObject USE WALL_SHAPE
}
DEF WALL_2 Solid {
  translation -1.2 0.05 0
  children [
    USE WALL_SHAPE
  ]
  name "solid(1)"
  boundingObject USE WALL_SHAPE
}
DEF WALL_3 Solid {
  translation 0 0.05 -1.2
  rotation 0 1 0 1.5708
  children [
    USE WALL_SHAPE
  ]
  name "solid(2)"
  boundingObject USE WALL_SHAPE
}
DEF WALL_4 Solid {
  translation 0 0.05 1.2
  rotation 0 1 0 1.5708
  children [
    USE WALL_SHAPE
  ]
  name "solid(3)"
  boundingObject USE WALL_SHAPE
}
DEF ROOT_G Robot {
  translation 1 0.15 -1
  children [
    Camera {
      translation 0.08 -0.08 0.1
      rotation 0 1 0 2.618
      children [
        DEF CAMERA_SHAPE Shape {
          appearance PBRAppearance {
          }
          geometry Box {
            size 0.005 0.005 0.005
          }
        }
      ]
      boundingObject USE CAMERA_SHAPE
      fieldOfView 0.01
      width 1
      height 1
      far 0.1
    }
    DEF CASTER Solid {
      translation 0 -0.105 -0.1
      children [
        Shape {
          geometry DEF CASTOR_BALL Sphere {
            radius 0.01
          }
        }
      ]
      name "solid(2)"
      contactMaterial "slippy"
      boundingObject USE CASTOR_BALL
      physics Physics {
      }
    }
    DEF BODY Group {
      children [
        DEF TOP Shape {
          appearance DEF BLUE PBRAppearance {
            baseColor 0 0 1
            metalness 0
          }
          geometry Box {
            size 0.17 0.01 0.2
          }
        }
        DEF LEFT_SIDE Transform {
          translation 0.08 -0.055 0
          children [
            DEF SIDE Shape {
              appearance USE BLUE
              geometry Box {
                size 0.01 0.1 0.2
              }
            }
          ]
        }
        DEF RIGHT_SIDE Transform {
          translation -0.08 -0.055 0
          children [
            USE SIDE
          ]
        }
        DEF BACK Transform {
          translation 0 -0.055 -0.095
          children [
            DEF BACK Shape {
              appearance USE BLUE
              geometry Box {
                size 0.15 0.1 0.01
              }
            }
          ]
        }
      ]
    }
    DEF RIGHT_WHEEL HingeJoint {
      jointParameters HingeJointParameters {
        position 2.3519943914640696e-11
        anchor 0.1 -0.075 0.06
      }
      device [
        RotationalMotor {
          name "wheel1"
          maxTorque 100
        }
      ]
      endPoint Solid {
        translation 0.1 -0.07500000000000735 0.06000129999506082
        rotation 4.067841848787345e-09 -4.067870990566227e-09 1 1.5708036414618511
        children [
          DEF WHEEL Shape {
            appearance PBRAppearance {
              baseColor 0.305882 0.898039 0.25098
              roughness 1
              metalness 0
            }
            geometry Cylinder {
              height 0.02
              radius 0.04
              subdivision 24
            }
          }
        ]
        boundingObject USE WHEEL
        physics Physics {
        }
      }
    }
    DEF LEFT_WHEEL HingeJoint {
      jointParameters HingeJointParameters {
        position -3.280296839556894e-11
        anchor -0.1 -0.075 0.06
      }
      device [
        RotationalMotor {
          name "wheel2"
          maxTorque 100
        }
      ]
      endPoint Solid {
        translation -0.0999996 -0.07499999999998745 0.060001300006888636
        rotation -6.7195199343278845e-09 6.7195633075012896e-09 1 1.570802907465455
        children [
          USE WHEEL
        ]
        name "solid(1)"
        boundingObject USE WHEEL
        physics Physics {
        }
      }
    }
    DEF DS_BOTTOM DistanceSensor {
      translation -0.08 -0.08 0.1
      rotation 0 1 0 -1.5707953071795862
      children [
        Shape {
          appearance PBRAppearance {
            baseColor 0.184314 0.596078 0.847059
            roughness 1
            metalness 0
          }
          geometry Box {
            size 0.01 0.01 0.01
          }
        }
      ]
      name "ds_bottom"
      lookupTable [
        0 0 0
        2 1000 0
      ]
    }
    DEF DS_TOP DistanceSensor {
      translation -0.08 -0.05 0.0999999
      rotation 0 1 0 -1.5707996938995747
      children [
        Shape {
          appearance PBRAppearance {
            baseColor 0.184314 0.596078 0.847059
            roughness 1
            metalness 0
          }
          geometry Box {
            size 0.01 0.01 0.01
          }
        }
      ]
      name "ds_top"
      lookupTable [
        0 0 0
        2 1000 0
      ]
    }
    GPS {
      translation 0 0.005 0
    }
    Compass {
      rotation 0 1 0 -1.5707953071795862
    }
    HingeJoint {
      jointParameters HingeJointParameters {
        axis 0 1 0
        anchor 0 0.04 0.07
      }
      device [
        RotationalMotor {
          name "servo_motor"
        }
      ]
      endPoint DistanceSensor {
        translation 0 0.04 0.07
        rotation 0.07096075410035216 -0.994951829364125 -0.07096075410035216 1.5758584235071784
        children [
          Shape {
            appearance PBRAppearance {
            }
            geometry Box {
              size 0.01 0.01 0.01
            }
          }
        ]
      }
    }
    LED {
      translation 0 0.01 0
      children [
        Shape {
          appearance PBRAppearance {
            roughness 1
            metalness 0
            emissiveIntensity 12
          }
          geometry Box {
            size 0.01 0.01 0.01
          }
        }
      ]
      color [
        1 0 0
        0 1 0
        0 0 1
        1 1 0
      ]
    }
  ]
  name "blueRobot"
  boundingObject USE BODY
  physics Physics {
    density -1
    mass 1
  }
  controller "main_controller"
}
root_g {
  hidden rotation_3 4.067841575037436e-09 -4.067871014093406e-09 1 1.570803641461852
  hidden rotation_4 -6.719519947254122e-09 6.719563535759925e-09 1 1.5708029074654555
  translation 0.9996342927663698 0.07776465206441362 1.002648509782327
  rotation -0.0014558512676722715 0.9998752754316399 0.015726222610296565 3.139309764783284
  name "redRobot"
  controller "camera_controller"
}
