#VRML_SIM R2021a utf8
WorldInfo {
  basicTimeStep 16
  coordinateSystem "NUE"
  contactProperties [
    ContactProperties {
      material2 "slippy"
      coulombFriction [
        0
      ]
    }
    ContactProperties {
      material2 "block"
      coulombFriction [
        0.01
      ]
    }
  ]
}
Viewpoint {
  orientation 0.5800690263189477 0.5877433548149894 0.5639837529363849 4.200959219408258
  position -0.13500146645665345 4.887075921460058 -0.24385168396966062
}
TexturedBackground {
}
TexturedBackgroundLight {
}
Floor {
  size 2.4 2.4
  appearance Asphalt {
  }
}
DEF Block_R1 Solid {
  translation -0.303153 0.0249755 0.592317
  rotation 0.16686656833226043 0.9636641493310073 -0.2085832104153186 -1.0219557955004574e-16
  children [
    DEF BOX_R Shape {
      appearance PBRAppearance {
        baseColor 1 0 0
        metalness 0
      }
      geometry Box {
        size 0.05 0.05 0.05
      }
    }
  ]
  name "solid(4)"
  contactMaterial "box"
  boundingObject USE BOX_R
  physics Physics {
  }
}
DEF Block_R2 Solid {
  translation -0.605285 0.0249755 -0.688195
  rotation -0.36750708266021803 0.9087236729683694 -0.19788842912472573 1.508061640284877e-16
  children [
    USE BOX_R
  ]
  name "solid(13)"
  contactMaterial "box"
  boundingObject USE BOX_R
  physics Physics {
  }
}
DEF Block_R3 Solid {
  translation -0.929313 0.0249755 0.722276
  rotation 0.3854770849102864 0.922717409074451 -4.081832740687572e-14 -1.1059688322464795e-17
  children [
    USE BOX_R
  ]
  name "solid(12)"
  boundingObject USE BOX_R
  physics Physics {
  }
}
DEF Block_R4 Solid {
  translation 0.35731 0.0249755 0.636046
  rotation 3.487333347262494e-14 0.6771592814607587 0.7358364679271808 -6.373130797970658e-17
  children [
    USE BOX_R
  ]
  name "solid(7)"
  boundingObject USE BOX_R
  physics Physics {
  }
}
DEF Block_B1 Solid {
  translation -0.277738 0.0249755 -0.488008
  rotation -0.48510915379872044 0.8735186698642385 0.04042576281655928 1.0545889842341123e-16
  children [
    DEF BOX_B Shape {
      appearance PBRAppearance {
        baseColor 0 0 1
        metalness 0
      }
      geometry Box {
        size 0.05 0.05 0.05
      }
    }
  ]
  name "solid(8)"
  boundingObject USE BOX_B
  physics Physics {
  }
}
DEF Block_B2 Solid {
  translation 0.0489301 0.0249755 -0.801936
  rotation 0.14272312242232377 0.9663321678178627 0.21408468363349212 -5.974163600408589e-17
  children [
    USE BOX_B
  ]
  name "solid(9)"
  boundingObject USE BOX_B
  physics Physics {
  }
}
DEF Block_B3 Solid {
  translation -0.786571 0.0249755 -0.0584789
  rotation -0.4247210096408211 0.8599067670138462 -0.28314733976055084 9.034002759480529e-17
  children [
    USE BOX_B
  ]
  name "solid(10)"
  boundingObject USE BOX_B
  physics Physics {
  }
}
DEF Block_B4 Solid {
  translation 0.514811 0.0249755 -0.0777602
  rotation 0.2074031990538158 0.9773757054189204 0.04148063981077562 -1.0277701679650052e-16
  children [
    USE BOX_B
  ]
  name "solid(11)"
  boundingObject USE BOX_B
  physics Physics {
  }
}
DEF Floor_colour Solid {
  translation 1 0.0001 1
  children [
    Shape {
      appearance PBRAppearance {
        baseColor 1 0 0
      }
      geometry Plane {
        size 0.4 0.4
      }
    }
  ]
  name "solid(6)"
}
DEF Floor_colour Solid {
  translation 1 0.0001 -1
  children [
    Shape {
      appearance PBRAppearance {
        baseColor 0 0 1
      }
      geometry Plane {
        size 0.4 0.4
      }
    }
  ]
  name "solid(5)"
}
DEF WALL_1 Solid {
  translation 1.2 0.05 0
  children [
    DEF WALL_SHAPE Shape {
      appearance PBRAppearance {
        baseColor 0 0.333333 0
        roughness 1
        metalness 0
      }
      geometry Box {
        size 0.02 0.1 2.38
      }
    }
  ]
  boundingObject USE WALL_SHAPE
}
DEF WALL_2 Solid {
  translation -1.2 0.05 0
  children [
    USE WALL_SHAPE
  ]
  name "solid(1)"
  boundingObject USE WALL_SHAPE
}
DEF WALL_3 Solid {
  translation 0 0.05 -1.2
  rotation 0 1 0 1.5708
  children [
    USE WALL_SHAPE
  ]
  name "solid(2)"
  boundingObject USE WALL_SHAPE
}
DEF WALL_4 Solid {
  translation 0 0.05 1.2
  rotation 0 1 0 1.5708
  children [
    USE WALL_SHAPE
  ]
  name "solid(3)"
  boundingObject USE WALL_SHAPE
}
DEF ROOT_G Robot {
  translation 1 0.15 -1
  children [
    Camera {
      translation 0.08 -0.08 0.1
      rotation 0 1 0 2.618
      children [
        DEF CAMERA_SHAPE Shape {
          appearance PBRAppearance {
          }
          geometry Box {
            size 0.005 0.005 0.005
          }
        }
      ]
      boundingObject USE CAMERA_SHAPE
      fieldOfView 0.01
      width 1
      height 1
      far 0.1
    }
    DEF CASTER Solid {
      translation 0 -0.105 -0.1
      children [
        Shape {
          geometry DEF CASTOR_BALL Sphere {
            radius 0.01
          }
        }
      ]
      name "solid(2)"
      contactMaterial "slippy"
      boundingObject USE CASTOR_BALL
      physics Physics {
      }
    }
    DEF BODY Group {
      children [
        DEF TOP Shape {
          appearance DEF BLUE PBRAppearance {
            baseColor 0 0 1
            metalness 0
          }
          geometry Box {
            size 0.17 0.01 0.2
          }
        }
        DEF LEFT_SIDE Transform {
          translation 0.08 -0.055 0
          children [
            DEF SIDE Shape {
              appearance USE BLUE
              geometry Box {
                size 0.01 0.1 0.2
              }
            }
          ]
        }
        DEF RIGHT_SIDE Transform {
          translation -0.08 -0.055 0
          children [
            USE SIDE
          ]
        }
        DEF BACK Transform {
          translation 0 -0.055 -0.095
          children [
            DEF BACK Shape {
              appearance USE BLUE
              geometry Box {
                size 0.15 0.1 0.01
              }
            }
          ]
        }
      ]
    }
    DEF RIGHT_WHEEL HingeJoint {
      jointParameters HingeJointParameters {
        position 2.3519943914640696e-11
        anchor 0.1 -0.075 0.06
      }
      device [
        RotationalMotor {
          name "wheel1"
          maxTorque 100
        }
      ]
      endPoint Solid {
        translation 0.1 -0.07500000000001482 0.06000129999506081
        rotation 7.254771041111198e-09 -7.254823475276384e-09 1 1.57080364146185
        children [
          DEF WHEEL Shape {
            appearance PBRAppearance {
              baseColor 0.305882 0.898039 0.25098
              roughness 1
              metalness 0
            }
            geometry Cylinder {
              height 0.02
              radius 0.04
              subdivision 24
            }
          }
        ]
        boundingObject USE WHEEL
        physics Physics {
        }
      }
    }
    DEF LEFT_WHEEL HingeJoint {
      jointParameters HingeJointParameters {
        position -3.280296839556894e-11
        anchor -0.1 -0.075 0.06
      }
      device [
        RotationalMotor {
          name "wheel2"
          maxTorque 100
        }
      ]
      endPoint Solid {
        translation -0.0999996 -0.07499999999997625 0.06000130000688864
        rotation -1.1164293208671057e-08 1.116436552026075e-08 0.9999999999999999 1.570802907465454
        children [
          USE WHEEL
        ]
        name "solid(1)"
        boundingObject USE WHEEL
        physics Physics {
        }
      }
    }
    DEF DS_BOTTOM DistanceSensor {
      translation -0.08 -0.08 0.1
      rotation 0 1 0 -1.5707953071795862
      children [
        Shape {
          appearance PBRAppearance {
            baseColor 0.184314 0.596078 0.847059
            roughness 1
            metalness 0
          }
          geometry Box {
            size 0.01 0.01 0.01
          }
        }
      ]
      name "ds_bottom"
      lookupTable [
        0 0 0
        1.4 700 0
      ]
    }
    DEF DS_TOP DistanceSensor {
      translation -0.08 -0.05 0.0999999
      rotation 0 1 0 -1.5707996938995747
      children [
        Shape {
          appearance PBRAppearance {
            baseColor 0.184314 0.596078 0.847059
            roughness 1
            metalness 0
          }
          geometry Box {
            size 0.01 0.01 0.01
          }
        }
      ]
      name "ds_top"
      lookupTable [
        0 0 0
        1.4 700 0
      ]
    }
    GPS {
      translation 0 0.005 0
    }
    Compass {
      rotation 0 1 0 -1.5707953071795862
    }
    LED {
      translation -0.03 0.01 0
      children [
        Shape {
          appearance PBRAppearance {
            roughness 1
            metalness 0
            emissiveIntensity 12
          }
          geometry Box {
            size 0.01 0.01 0.01
          }
        }
      ]
      color [
        1 0 0
        0 1 0
        0 0 1
        1 1 0
      ]
    }
    LED {
      translation -0.01 0.01 0
      children [
        Shape {
          appearance PBRAppearance {
            roughness 1
            metalness 0
            emissiveIntensity 12
          }
          geometry Box {
            size 0.01 0.01 0.01
          }
        }
      ]
      name "led(1)"
      color [
        1 0 0
        0 1 0
        0 0 1
        1 1 0
      ]
    }
    LED {
      translation 0.01 0.01 0
      children [
        Shape {
          appearance PBRAppearance {
            roughness 1
            metalness 0
            emissiveIntensity 12
          }
          geometry Box {
            size 0.01 0.01 0.01
          }
        }
      ]
      name "led(2)"
      color [
        1 0 0
        0 1 0
        0 0 1
        1 1 0
      ]
    }
    LED {
      translation 0.03 0.01 0
      children [
        Shape {
          appearance PBRAppearance {
            roughness 1
            metalness 0
            emissiveIntensity 12
          }
          geometry Box {
            size 0.01 0.01 0.01
          }
        }
      ]
      name "led(3)"
      color [
        1 0 0
        0 1 0
        0 0 1
        1 1 0
      ]
    }
  ]
  name "blueRobot"
  boundingObject USE BODY
  physics Physics {
    density -1
    mass 1
  }
  controller "main_controller"
}
root_g {
  hidden rotation_3 7.172451839549702e-09 -7.172503671575142e-09 1 1.57080364146185
  hidden rotation_4 -1.1049483574813436e-08 1.1049555130876265e-08 0.9999999999999999 1.570802907465454
  translation 0.9996342927663698 0.07776465206441362 1.002648509782327
  rotation -0.0014558512676722715 0.9998752754316399 0.015726222610296565 3.139309764783284
}
