#VRML_SIM R2021a utf8
WorldInfo {
  basicTimeStep 16
  coordinateSystem "NUE"
  contactProperties [
    ContactProperties {
      material2 "slippy"
      coulombFriction [
        0
      ]
    }
    ContactProperties {
      material2 "block"
      coulombFriction [
        0.01
      ]
    }
  ]
}
Viewpoint {
  orientation 0.03369387042859633 0.962160128750232 0.2703934350883505 3.321346570458585
  position 0.29466483111603986 1.0844336711540694 -2.179501682272587
}
TexturedBackground {
}
TexturedBackgroundLight {
}
Solid {
  children [
    Shape {
      appearance Asphalt {
      }
      geometry IndexedFaceSet {
        coord Coordinate {
          point [
            -1.2 0 -1.2
            1.2 0 -1.2
            -1.2 0 1.2
            1.2 0 1.2
          ]
        }
        texCoord TextureCoordinate {
          point [
            0 0
            4.8 0
            0 4.8
            4.8 4.8
          ]
        }
        coordIndex [
          0, 2, 3, 1, -1
        ]
        texCoordIndex [
          2, 0, 1, 3, -1
        ]
      }
    }
  ]
  name "floor"
  model "floor"
  boundingObject Plane {
    size 2.4 2.4
  }
  locked TRUE
}
DEF Block_R1 Solid {
  translation 0.620717 0.0249755 -0.806451
  rotation -0.21164604087594807 0.9625683163005732 -0.16931683270075745 -1.0071665874107654e-16
  children [
    DEF BOX_R Shape {
      appearance PBRAppearance {
        baseColor 1 0 0
        metalness 0
      }
      geometry Box {
        size 0.05 0.05 0.05
      }
    }
  ]
  name "solid(4)"
  contactMaterial "box"
  boundingObject USE BOX_R
  physics Physics {
  }
}
DEF Block_R2 Solid {
  translation 1 0.024975474999407 0.3
  rotation -0.06176052670005056 0.9860759964260168 -0.15440131675011942 1.380576443353786e-16
  children [
    USE BOX_R
  ]
  name "solid(13)"
  contactMaterial "block"
  boundingObject USE BOX_R
  physics Physics {
  }
}
DEF Block_R3 Solid {
  translation -1 0.024975474999406996 -0.5
  rotation 0.28416813628816256 0.4387307866846905 -0.8525044088645788 -1.5002584280726777e-17
  children [
    USE BOX_R
  ]
  name "solid(12)"
  boundingObject USE BOX_R
  physics Physics {
  }
}
DEF Block_R4 Solid {
  translation 0.1 0.024975474999407 1.1
  rotation -0.6229317470512805 0.649472476236125 0.4360522229359179 -6.843857990447598e-17
  children [
    USE BOX_R
  ]
  name "solid(7)"
  boundingObject USE BOX_R
  physics Physics {
  }
}
DEF Block_B1 Solid {
  translation -1.1 0.024975474999406996 1
  rotation -0.2817140454308273 0.9172101139946013 -0.2817140454308382 1.0593293229765844e-16
  children [
    DEF BOX_B Shape {
      appearance PBRAppearance {
        baseColor 0 0 1
        metalness 0
      }
      geometry Box {
        size 0.05 0.05 0.05
      }
    }
  ]
  name "solid(8)"
  boundingObject USE BOX_B
  physics Physics {
  }
}
DEF Block_B2 Solid {
  translation 0.029999999999999985 0.024975474999406996 0.72
  rotation 0.07538708258689157 0.9943005458904632 0.07538708258689819 -5.655155058755124e-17
  children [
    USE BOX_B
  ]
  name "solid(9)"
  boundingObject USE BOX_B
  physics Physics {
  }
}
DEF Block_B3 Solid {
  translation -0.85 0.024975474999407 -0.2
  rotation -0.5811347950543398 0.8138073174757956 -4.588184627553168e-15 9.536915335469669e-17
  children [
    USE BOX_B
  ]
  name "solid(10)"
  boundingObject USE BOX_B
  physics Physics {
  }
}
DEF Block_B4 Solid {
  translation 1 0.024975474999406996 0.7
  rotation -0.2868557182143074 0.9245071242021694 0.250998753437519 -1.1889618770299535e-16
  children [
    USE BOX_B
  ]
  name "solid(11)"
  boundingObject USE BOX_B
  physics Physics {
  }
}
DEF Floor_colour Solid {
  translation 1 0.0001 1
  children [
    Shape {
      appearance PBRAppearance {
        baseColor 1 0 0
      }
      geometry Plane {
        size 0.4 0.4
      }
    }
  ]
  name "solid(6)"
}
DEF Floor_colour Solid {
  translation 1 0.0001 -1
  children [
    Shape {
      appearance PBRAppearance {
        baseColor 0 0 1
      }
      geometry Plane {
        size 0.4 0.4
      }
    }
  ]
  name "solid(5)"
}
DEF WALL_1 Solid {
  translation 1.2 0.05 0
  children [
    DEF WALL_SHAPE Shape {
      appearance PBRAppearance {
        baseColor 0 0.333333 0
        roughness 1
        metalness 0
      }
      geometry Box {
        size 0.02 0.1 2.38
      }
    }
  ]
  boundingObject USE WALL_SHAPE
}
DEF WALL_2 Solid {
  translation -1.2 0.05 0
  children [
    USE WALL_SHAPE
  ]
  name "solid(1)"
  boundingObject USE WALL_SHAPE
}
DEF WALL_3 Solid {
  translation 0 0.05 -1.2
  rotation 0 1 0 1.5708
  children [
    USE WALL_SHAPE
  ]
  name "solid(2)"
  boundingObject USE WALL_SHAPE
}
DEF WALL_4 Solid {
  translation 0 0.05 1.2
  rotation 0 1 0 1.5708
  children [
    USE WALL_SHAPE
  ]
  name "solid(3)"
  boundingObject USE WALL_SHAPE
}
DEF ROOT_G Robot {
  translation 0.796893 0.06 -0.911581
  rotation -0.02863129844525376 0.9995899457199361 0.0004349309763822342 0.0632945
  scale 0.3 0.3 0.3
  children [
    Camera {
      translation 0.08 -0.04 0.1
      rotation 0 1 0 2.618
      children [
        DEF CAMERA_SHAPE Shape {
          appearance PBRAppearance {
          }
          geometry Box {
            size 0.005 0.005 0.005
          }
        }
      ]
      boundingObject USE CAMERA_SHAPE
      fieldOfView 0.01
      width 1
      height 1
      far 0.1
    }
    DEF CASTER Solid {
      translation 0 -0.105 -0.1
      children [
        Shape {
          geometry DEF CASTOR_BALL Sphere {
            radius 0.01
          }
        }
      ]
      name "solid(2)"
      contactMaterial "slippy"
      boundingObject USE CASTOR_BALL
      physics Physics {
      }
    }
    DEF BODY Group {
      children [
        DEF TOP Shape {
          appearance DEF BLUE PBRAppearance {
            baseColor 0 0 1
            metalness 0
          }
          geometry Box {
            size 0.17 0.01 0.2
          }
        }
        DEF LEFT_SIDE Transform {
          translation 0.08 -0.055 0
          children [
            DEF SIDE Shape {
              appearance USE BLUE
              geometry Box {
                size 0.01 0.1 0.2
              }
            }
          ]
        }
        DEF RIGHT_SIDE Transform {
          translation -0.08 -0.055 0
          children [
            USE SIDE
          ]
        }
        DEF BACK Transform {
          translation 0 -0.055 -0.095
          children [
            DEF BACK Shape {
              appearance USE BLUE
              geometry Box {
                size 0.15 0.1 0.01
              }
            }
          ]
        }
      ]
    }
    DEF RIGHT_WHEEL HingeJoint {
      jointParameters HingeJointParameters {
        position -2.3197712428115036
        anchor 0.1 -0.075 0.06
      }
      device [
        RotationalMotor {
          name "wheel1"
          maxTorque 100
        }
      ]
      endPoint Solid {
        translation 0.10018342320441595 -0.07478189952510293 0.060033991122595255
        rotation 0.6765229256792993 -0.6741597839305119 -0.29635336468663026 3.7237028411946484
        children [
          DEF WHEEL Shape {
            appearance PBRAppearance {
              baseColor 0.305882 0.898039 0.25098
              roughness 1
              metalness 0
            }
            geometry Cylinder {
              height 0.02
              radius 0.04
              subdivision 24
            }
          }
        ]
        boundingObject USE WHEEL
        physics Physics {
        }
      }
    }
    DEF LEFT_WHEEL HingeJoint {
      jointParameters HingeJointParameters {
        position 2.3197715204928038
        anchor -0.1 -0.075 0.06
      }
      device [
        RotationalMotor {
          name "wheel2"
          maxTorque 100
        }
      ]
      endPoint Solid {
        translation -0.10023359622694455 -0.07516440363048241 0.06002595308423548
        rotation -0.673509743978534 0.6758810524643504 -0.29928151911812356 3.7172918162730095
        children [
          USE WHEEL
        ]
        name "solid(1)"
        boundingObject USE WHEEL
        physics Physics {
        }
      }
    }
    DEF DS_RIGHT DistanceSensor {
      translation -0.03 0 0.1
      rotation 0 1 0 -1.87079
      children [
        Shape {
          appearance PBRAppearance {
            baseColor 0.184314 0.596078 0.847059
            roughness 1
            metalness 0
          }
          geometry Box {
            size 0.01 0.01 0.01
          }
        }
      ]
      name "ds_right"
    }
    DEF DS_LEFT DistanceSensor {
      translation 0.03 0 0.1
      rotation 0 1 0 -1.27079
      children [
        Shape {
          appearance PBRAppearance {
            baseColor 0.184314 0.596078 0.847059
            roughness 1
            metalness 0
          }
          geometry Box {
            size 0.01 0.01 0.01
          }
        }
      ]
      name "ds_left"
      lookupTable [
        0 0 0
        1000 1000 0
      ]
      type "laser"
    }
    GPS {
      translation 0 0.005 0
    }
    Compass {
      rotation 0 1 0 -1.5707953071795862
    }
    HingeJoint {
      jointParameters HingeJointParameters {
        axis 0 1 0
        anchor 0 0.04 0.07
      }
      device [
        RotationalMotor {
          name "servo_motor"
        }
      ]
      endPoint DistanceSensor {
        translation 0 0.04 0.07
        rotation 0.07096075410035216 -0.994951829364125 -0.07096075410035216 1.5758584235071784
        children [
          Shape {
            appearance PBRAppearance {
            }
            geometry Box {
              size 0.01 0.01 0.01
            }
          }
        ]
      }
    }
    LED {
      translation 0 0.01 0
      children [
        Shape {
          appearance PBRAppearance {
            roughness 1
            metalness 0
            emissiveIntensity 12
          }
          geometry Box {
            size 0.01 0.01 0.01
          }
        }
      ]
      color [
        1 0 0
        0 1 0
        0 0 1
        1 1 0
      ]
    }
  ]
  name "blueRobot"
  boundingObject USE BODY
  physics Physics {
    density -1
    mass 1
  }
  controller "main_controller"
}
root_g {
  translation 0.9996342930387163 0.07776465210795785 1.0026485098175741
  rotation -0.0014558508003569043 0.9998752754288265 0.015726222832442665 3.139309764769196
}
